<?xml version="1.0" encoding="utf-8"?>
<!-- This URDF was automatically created by SolidWorks to URDF Exporter! Originally created by Stephen Brawner (brawner@gmail.com) 
     Commit Version: 1.6.0-4-g7f85cfe  Build Version: 1.6.7995.38578
     For more information, please see http://wiki.ros.org/sw_urdf_exporter -->
<robot
  name="Dora2">
   <link
    name="base_link">
    <inertial>
      <origin
        xyz="-0.026491 -5.0156E-08 0.050159"
        rpy="0 0 0" />
      <mass
        value="10.009" />
      <inertia
        ixx="0.034427"
        ixy="-9.2543E-07"
        ixz="1.0661E-05"
        iyy="0.023503"
        iyz="1.2551E-05"
        izz="0.022038" />
    </inertial>
    <visual>
      <origin
        xyz="0 0 0"
        rpy="0 0 0" />
      <geometry>
        <mesh
          filename="base_link.STL" />
      </geometry>
      <material
        name="">
        <color
          rgba="0.89804 0.91765 0.92941 1" />
      </material>
    </visual>
    <!-- <collision>
      <origin
        xyz="0 0 0"
        rpy="0 0 0" />
      <geometry>
        <mesh
          filename="base_link.STL" />
      </geometry>
    </collision> -->
    <collision>
      <origin
        xyz="0 0. 0.1"
        rpy="0 0 0" />
      <geometry>
        <box size="0.25 0.22 0.32"/>
      </geometry>
    </collision>
  </link>
  <link
    name="l_arm_shoulder_pitch_Link">
    <inertial>
      <origin
        xyz="0.0012154 0.0085194 0.04695"
        rpy="0 0 0" />
      <mass
        value="0.59249" />
      <inertia
        ixx="0.00026821"
        ixy="-1.588E-06"
        ixz="-3.7101E-06"
        iyy="0.00020453"
        iyz="-8.9591E-06"
        izz="0.00021179" />
    </inertial>
    <visual>
      <origin
        xyz="0 0 0"
        rpy="0 0 0" />
      <geometry>
        <mesh
          filename="l_arm_shoulder_pitch_Link.STL" />
      </geometry>
      <material
        name="">
        <color
          rgba="0.64706 0.61961 0.58824 1" />
      </material>
    </visual>
    <!-- <collision>
      <origin
        xyz="0 0 0"
        rpy="0 0 0" />
      <geometry>
        <mesh
          filename="l_arm_shoulder_pitch_Link.STL" />
      </geometry>
    </collision> -->
  </link>
  <joint
    name="l_arm_shoulder_pitch_joint"
    type="fixed">
    <origin
      xyz="-0.00094467 0.18217 0.2078"
      rpy="-1.2217 0.2618 0" />
    <parent
      link="base_link" />
    <child
      link="l_arm_shoulder_pitch_Link" />
    <axis
      xyz="0 0 1" />
    <limit
      lower="-2"
      upper="2"
      effort="36"
      velocity="6.28" />
  </joint>
  <link
    name="l_arm_shoulder_roll_Link">
    <inertial>
      <origin
        xyz="6.5565E-05 -2.5633E-06 -0.058315"
        rpy="0 0 0" />
      <mass
        value="0.53087" />
      <inertia
        ixx="0.00033546"
        ixy="-5.1467E-08"
        ixz="-4.6685E-05"
        iyy="0.00037342"
        iyz="7.4288E-09"
        izz="0.00026136" />
    </inertial>
    <visual>
      <origin
        xyz="0 0 0"
        rpy="0 0 0" />
      <geometry>
        <mesh
          filename="l_arm_shoulder_roll_Link.STL" />
      </geometry>
      <material
        name="">
        <color
          rgba="0.89804 0.91765 0.92941 1" />
      </material>
    </visual>
    <!-- <collision>
      <origin
        xyz="0 0 0"
        rpy="0 0 0" />
      <geometry>
        <mesh
          filename="l_arm_shoulder_roll_Link.STL" />
      </geometry>
    </collision> -->
  </link>
  <joint
    name="l_arm_shoulder_roll_joint"
    type="fixed">
    <origin
      xyz="0.00094467 0.013172 0.064412"
      rpy="1.2217 0 0" />
    <parent
      link="l_arm_shoulder_pitch_Link" />
    <child
      link="l_arm_shoulder_roll_Link" />
    <axis
      xyz="1 0 0" />
    <limit
      lower="-3"
      upper="0"
      effort="36"
      velocity="6.28" />
  </joint>
  <link
    name="l_arm_shoulder_yaw_Link">
    <inertial>
      <origin
        xyz="0.0011882 0.0067383 -0.053586"
        rpy="0 0 0" />
      <mass
        value="0.67878" />
      <inertia
        ixx="0.00031565"
        ixy="2.9333E-08"
        ixz="-7.6862E-08"
        iyy="0.0003551"
        iyz="1.395E-05"
        izz="0.00023355" />
    </inertial>
    <visual>
      <origin
        xyz="0 0 0"
        rpy="0 0 0" />
      <geometry>
        <mesh
          filename="l_arm_shoulder_yaw_Link.STL" />
      </geometry>
      <material
        name="">
        <color
          rgba="0.89804 0.91765 0.92941 1" />
      </material>
    </visual>
    <!-- <collision>
      <origin
        xyz="0 0 0"
        rpy="0 0 0" />
      <geometry>
        <mesh
          filename="l_arm_shoulder_yaw_Link.STL" />
      </geometry>
    </collision> -->
  </link>
  <joint
    name="l_arm_shoulder_yaw_joint"
    type="fixed">
    <origin
      xyz="-0.0012652 0 -0.094377"
      rpy="0 0 0" />
    <parent
      link="l_arm_shoulder_roll_Link" />
    <child
      link="l_arm_shoulder_yaw_Link" />
    <axis
      xyz="0 0 1" />
    <limit
      lower="-2"
      upper="2"
      effort="36"
      velocity="6.28" />
  </joint>
  <link
    name="l_arm_elbow_Link">
    <inertial>
      <origin
        xyz="5.8478E-06 5.3289E-05 -0.0048248"
        rpy="0 0 0" />
      <mass
        value="0.44883" />
      <inertia
        ixx="0.00016487"
        ixy="-2.9245E-07"
        ixz="-1.6498E-07"
        iyy="0.00014407"
        iyz="2.8015E-08"
        izz="0.0002086" />
    </inertial>
    <visual>
      <origin
        xyz="0 0 0"
        rpy="0 0 0" />
      <geometry>
        <mesh
          filename="l_arm_elbow_Link.STL" />
      </geometry>
      <material
        name="">
        <color
          rgba="0.89804 0.91765 0.92941 1" />
      </material>
    </visual>
    <!-- <collision>
      <origin
        xyz="0 0 0"
        rpy="0 0 0" />
      <geometry>
        <mesh
          filename="l_arm_elbow_Link.STL" />
      </geometry>
    </collision> -->
  </link>
  <joint
    name="l_arm_elbow_joint"
    type="fixed">
    <origin
      xyz="0.0012652 0 -0.11612"
      rpy="0 -1.047 0" />
    <parent
      link="l_arm_shoulder_yaw_Link" />
    <child
      link="l_arm_elbow_Link" />
    <axis
      xyz="0 1 0" />
    <limit
      lower="-1.5"
      upper="1.5"
      effort="36"
      velocity="6.28" />
  </joint>
  <link
    name="l_arm_wrist_yaw1_Link">
    <inertial>
      <origin
        xyz="0.00063942 0.0031627 -0.057666"
        rpy="0 0 0" />
      <mass
        value="0.81511" />
      <inertia
        ixx="0.00035549"
        ixy="-3.7663E-08"
        ixz="-1.9544E-07"
        iyy="0.00043001"
        iyz="1.7696E-05"
        izz="0.00024625" />
    </inertial>
    <visual>
      <origin
        xyz="0 0 0"
        rpy="0 0 0" />
      <geometry>
        <mesh
          filename="l_arm_wrist_yaw1_Link.STL" />
      </geometry>
      <material
        name="">
        <color
          rgba="0.64706 0.61961 0.58824 1" />
      </material>
    </visual>
    <collision>
      <origin
        xyz="0 0 0"
        rpy="0 0 0" />
      <geometry>
        <mesh
          filename="l_arm_wrist_yaw1_Link.STL" />
      </geometry>
    </collision>
  </link>
  <joint
    name="l_arm_wrist_yaw1_joint"
    type="fixed">
    <origin
      xyz="-0.00068626 2.7758E-05 -0.033039"
      rpy="0 0 0" />
    <parent
      link="l_arm_elbow_Link" />
    <child
      link="l_arm_wrist_yaw1_Link" />
    <axis
      xyz="0 0 1" />
    <limit
      lower="0"
      upper="0"
      effort="36"
      velocity="6.28" />
  </joint>
  <link
    name="l_arm_wrist_pitch_Link">
    <inertial>
      <origin
        xyz="-8.7585E-07 -5.7309E-05 -0.0094885"
        rpy="0 0 0" />
      <mass
        value="0.44562" />
      <inertia
        ixx="0.00016272"
        ixy="3.1754E-07"
        ixz="-1.954E-07"
        iyy="0.00014662"
        iyz="-2.7335E-08"
        izz="0.00020462" />
    </inertial>
    <visual>
      <origin
        xyz="0 0 0"
        rpy="0 0 0" />
      <geometry>
        <mesh
          filename="l_arm_wrist_pitch_Link.STL" />
      </geometry>
      <material
        name="">
        <color
          rgba="0.89804 0.91765 0.92941 1" />
      </material>
    </visual>
    <!-- <collision>
      <origin
        xyz="0 0 0"
        rpy="0 0 0" />
      <geometry>
        <mesh
          filename="l_arm_wrist_pitch_Link.STL" />
      </geometry>
    </collision> -->
  </link>
  <joint
    name="l_arm_wrist_pitch_joint"
    type="fixed">
    <origin
      xyz="0.00068626 -2.7758E-05 -0.12886"
      rpy="0 0 0" />
    <parent
      link="l_arm_wrist_yaw1_Link" />
    <child
      link="l_arm_wrist_pitch_Link" />
    <axis
      xyz="0 1 0" />
    <limit
      lower="0"
      upper="0"
      effort="0"
      velocity="0" />
  </joint>
  <link
    name="l_arm_wrist_yaw2_Link">
    <inertial>
      <origin
        xyz="-0.0046238 0.001297 -0.051174"
        rpy="0 0 0" />
      <mass
        value="0.66283" />
      <inertia
        ixx="0.00030582"
        ixy="-3.1183E-06"
        ixz="-6.7398E-06"
        iyy="0.00032338"
        iyz="1.0341E-05"
        izz="0.00024221" />
    </inertial>
    <visual>
      <origin
        xyz="0 0 0"
        rpy="0 0 0" />
      <geometry>
        <mesh
          filename="l_arm_wrist_yaw2_Link.STL" />
      </geometry>
      <material
        name="">
        <color
          rgba="0.89804 0.91765 0.92941 1" />
      </material>
    </visual>
    <!-- <collision>
      <origin
        xyz="0 0 0"
        rpy="0 0 0" />
      <geometry>
        <mesh
          filename="l_arm_wrist_yaw2_Link.STL" />
      </geometry>
    </collision> -->
  </link>
  <joint
    name="l_arm_wrist_yaw2_joint"
    type="fixed">
    <origin
      xyz="0.0012607 -0.00010591 -0.033777"
      rpy="0 0 0" />
    <parent
      link="l_arm_wrist_pitch_Link" />
    <child
      link="l_arm_wrist_yaw2_Link" />
    <axis
      xyz="0 0 1" />
    <limit
      lower="0"
      upper="0"
      effort="0"
      velocity="0" />
  </joint>
  <link
    name="l_arm_claw_link">
    <inertial>
      <origin
        xyz="0.014927 -0.00021226 -0.047831"
        rpy="0 0 0" />
      <mass
        value="0.13307" />
      <inertia
        ixx="0.00016061"
        ixy="-3.6552E-06"
        ixz="1.1664E-05"
        iyy="0.00011707"
        iyz="1.0687E-05"
        izz="7.2166E-05" />
    </inertial>
    <visual>
      <origin
        xyz="0 0 0"
        rpy="0 0 0" />
      <geometry>
        <mesh
          filename="l_arm_claw_link.STL" />
      </geometry>
      <material
        name="">
        <color
          rgba="1 1 1 1" />
      </material>
    </visual>
    <collision>
      <origin
        xyz="0 0 0"
        rpy="0 0 0" />
      <geometry>
        <mesh
          filename="l_arm_claw_link.STL" />
      </geometry>
    </collision>
  </link>
  <joint
    name="l_arm_claw_joint"
    type="fixed">
    <origin
      xyz="0.00013819 0.00010591 -0.045636"
      rpy="0 0 0" />
    <parent
      link="l_arm_wrist_yaw2_Link" />
    <child
      link="l_arm_claw_link" />
    <axis
      xyz="0 1 0" />
    <limit
      lower="0"
      upper="0"
      effort="0"
      velocity="0" />
  </joint>

  <link
    name="r_arm_shoulder_pitch_Link">
    <inertial>
      <origin
        xyz="0.0012156 -0.0085193 0.04695"
        rpy="0 0 0" />
      <mass
        value="0.59248" />
      <inertia
        ixx="0.00026821"
        ixy="1.5881E-06"
        ixz="-3.7098E-06"
        iyy="0.00020453"
        iyz="8.9597E-06"
        izz="0.00021179" />
    </inertial>
    <visual>
      <origin
        xyz="0 0 0"
        rpy="0 0 0" />
      <geometry>
        <mesh
          filename="r_arm_shoulder_pitch_Link.STL" />
      </geometry>
      <material
        name="">
        <color
          rgba="1 1 1 1" />
      </material>
    </visual>
    <!-- <collision>
      <origin
        xyz="0 0 0"
        rpy="0 0 0" />
      <geometry>
        <mesh
          filename="r_arm_shoulder_pitch_Link.STL" />
      </geometry>
    </collision> -->
  </link>
  <joint
    name="r_arm_shoulder_pitch_joint"
    type="fixed">
    <origin
      xyz="-0.00094467 -0.18217 0.2078"
      rpy="1.2217 0.2618 0" />
    <parent
      link="base_link" />
    <child
      link="r_arm_shoulder_pitch_Link" />
    <axis
      xyz="0 0 1" />
    <limit
      lower="-2"
      upper="2"
      effort="36"
      velocity="6.28" />
  </joint>
  <link
    name="r_arm_shoulder_roll_Link">
    <inertial>
      <origin
        xyz="6.5061E-05 2.5217E-06 -0.058315"
        rpy="0 0 0" />
      <mass
        value="0.53088" />
      <inertia
        ixx="0.00033544"
        ixy="5.1545E-08"
        ixz="-4.6685E-05"
        iyy="0.00037344"
        iyz="-2.0186E-09"
        izz="0.00026137" />
    </inertial>
    <visual>
      <origin
        xyz="0 0 0"
        rpy="0 0 0" />
      <geometry>
        <mesh
          filename="r_arm_shoulder_roll_Link.STL" />
      </geometry>
      <material
        name="">
        <color
          rgba="1 1 1 1" />
      </material>
    </visual>
    <!-- <collision>
      <origin
        xyz="0 0 0"
        rpy="0 0 0" />
      <geometry>
        <mesh
          filename="r_arm_shoulder_roll_Link.STL" />
      </geometry>
    </collision> -->
  </link>
  <joint
    name="r_arm_shoulder_roll_joint"
    type="fixed">
    <origin
      xyz="0.00094467 -0.013172 0.064412"
      rpy="-1.2217 0 0" />
    <parent
      link="r_arm_shoulder_pitch_Link" />
    <child
      link="r_arm_shoulder_roll_Link" />
    <axis
      xyz="1 0 0" />
    <limit
      lower="0"
      upper="3"
      effort="36"
      velocity="6.28" />
  </joint>
  <link
    name="r_arm_shoulder_yaw_Link">
    <inertial>
      <origin
        xyz="0.0011882 -0.0067383 -0.053586"
        rpy="0 0 0" />
      <mass
        value="0.67878" />
      <inertia
        ixx="0.00031565"
        ixy="-2.9283E-08"
        ixz="-7.7015E-08"
        iyy="0.0003551"
        iyz="-1.395E-05"
        izz="0.00023355" />
    </inertial>
    <visual>
      <origin
        xyz="0 0 0"
        rpy="0 0 0" />
      <geometry>
        <mesh
          filename="r_arm_shoulder_yaw_Link.STL" />
      </geometry>
      <material
        name="">
        <color
          rgba="1 1 1 1" />
      </material>
    </visual>
    <!-- <collision>
      <origin
        xyz="0 0 0"
        rpy="0 0 0" />
      <geometry>
        <mesh
          filename="r_arm_shoulder_yaw_Link.STL" />
      </geometry>
    </collision> -->
  </link>
  <joint
    name="r_arm_shoulder_yaw_joint"
    type="fixed">
    <origin
      xyz="-0.0012652 0 -0.094377"
      rpy="0 0 0" />
    <parent
      link="r_arm_shoulder_roll_Link" />
    <child
      link="r_arm_shoulder_yaw_Link" />
    <axis
      xyz="0 0 1" />
    <limit
      lower="-2"
      upper="2"
      effort="0"
      velocity="0" />
  </joint>
  <link
    name="r_arm_elbow_Link">
    <inertial>
      <origin
        xyz="5.8478E-06 -5.3289E-05 -0.0048248"
        rpy="0 0 0" />
      <mass
        value="0.44883" />
      <inertia
        ixx="0.00016487"
        ixy="2.9245E-07"
        ixz="-1.6498E-07"
        iyy="0.00014407"
        iyz="-2.8015E-08"
        izz="0.0002086" />
    </inertial>
    <visual>
      <origin
        xyz="0 0 0"
        rpy="0 0 0" />
      <geometry>
        <mesh
          filename="r_arm_elbow_Link.STL" />
      </geometry>
      <material
        name="">
        <color
          rgba="1 1 1 1" />
      </material>
    </visual>
    <!-- <collision>
      <origin
        xyz="0 0 0"
        rpy="0 0 0" />
      <geometry>
        <mesh
          filename="r_arm_elbow_Link.STL" />
      </geometry>
    </collision> -->
  </link>
  <joint
    name="r_arm_elbow_joint"
    type="fixed">
    <origin
      xyz="0.0012652 0 -0.11612"
      rpy="0 -1.047 0" />
    <parent
      link="r_arm_shoulder_yaw_Link" />
    <child
      link="r_arm_elbow_Link" />
    <axis
      xyz="0 1 0" />
    <limit
      lower="-1.5"
      upper="1.5"
      effort="36"
      velocity="6.28" />
  </joint>
  <link
    name="r_arm_wrist_yaw1_Link">
    <inertial>
      <origin
        xyz="0.00063942 -0.0031627 -0.057666"
        rpy="0 0 0" />
      <mass
        value="0.81511" />
      <inertia
        ixx="0.00035549"
        ixy="3.7663E-08"
        ixz="-1.9544E-07"
        iyy="0.00043001"
        iyz="-1.7696E-05"
        izz="0.00024625" />
    </inertial>
    <visual>
      <origin
        xyz="0 0 0"
        rpy="0 0 0" />
      <geometry>
        <mesh
          filename="r_arm_wrist_yaw1_Link.STL" />
      </geometry>
      <material
        name="">
        <color
          rgba="1 1 1 1" />
      </material>
    </visual>
    <collision>
      <origin
        xyz="0 0 0"
        rpy="0 0 0" />
      <geometry>
        <mesh
          filename="r_arm_wrist_yaw1_Link.STL" />
      </geometry>
    </collision>
  </link>
  <joint
    name="r_arm_wrist_yaw1_joint"
    type="fixed">
    <origin
      xyz="-0.00068626 -2.7758E-05 -0.033039"
      rpy="0 0 0" />
    <parent
      link="r_arm_elbow_Link" />
    <child
      link="r_arm_wrist_yaw1_Link" />
    <axis
      xyz="0 0 1" />
    <limit
      lower="0"
      upper="0"
      effort="0"
      velocity="0" />
  </joint>
  <link
    name="r_arm_wrist_pitch_Link">
    <inertial>
      <origin
        xyz="-4.6206E-05 6.1016E-05 -0.010617"
        rpy="0 0 0" />
      <mass
        value="0.44562" />
      <inertia
        ixx="7.367E-05"
        ixy="-1.093E-07"
        ixz="-2.03E-07"
        iyy="5.7846E-05"
        iyz="9.4515E-09"
        izz="8.7435E-05" />
    </inertial>
    <visual>
      <origin
        xyz="0 0 0"
        rpy="0 0 0" />
      <geometry>
        <mesh
          filename="r_arm_wrist_pitch_Link.STL" />
      </geometry>
      <material
        name="">
        <color
          rgba="1 1 1 1" />
      </material>
    </visual>
    <!-- <collision>
      <origin
        xyz="0 0 0"
        rpy="0 0 0" />
      <geometry>
        <mesh
          filename="r_arm_wrist_pitch_Link.STL" />
      </geometry>
    </collision> -->
  </link>
  <joint
    name="r_arm_wrist_pitch_joint"
    type="fixed">
    <origin
      xyz="0.00068626 2.7758E-05 -0.12886"
      rpy="0 0 0" />
    <parent
      link="r_arm_wrist_yaw1_Link" />
    <child
      link="r_arm_wrist_pitch_Link" />
    <axis
      xyz="0 1 0" />
    <limit
      lower="0"
      upper="0"
      effort="0"
      velocity="0" />
  </joint>
  <link
    name="r_arm_wrist_yaw2_Link">
    <inertial>
      <origin
        xyz="0.0074699 0.0029676 -0.055476"
        rpy="0 0 0" />
      <mass
        value="0.66283" />
      <inertia
        ixx="0.00021748"
        ixy="2.4815E-06"
        ixz="7.3738E-06"
        iyy="0.00020586"
        iyz="9.927E-06"
        izz="0.00015306" />
    </inertial>
    <visual>
      <origin
        xyz="0 0 0"
        rpy="0 0 0" />
      <geometry>
        <mesh
          filename="r_arm_wrist_yaw2_Link.STL" />
      </geometry>
      <material
        name="">
        <color
          rgba="1 1 1 1" />
      </material>
    </visual>
    <!-- <collision>
      <origin
        xyz="0 0 0"
        rpy="0 0 0" />
      <geometry>
        <mesh
          filename="r_arm_wrist_yaw2_Link.STL" />
      </geometry>
    </collision> -->
  </link>
  <joint
    name="r_arm_wrist_yaw2_joint"
    type="fixed">
    <origin
      xyz="-0.0012648 -3.2137E-05 -0.033777"
      rpy="0 0 0" />
    <parent
      link="r_arm_wrist_pitch_Link" />
    <child
      link="r_arm_wrist_yaw2_Link" />
    <axis
      xyz="0 0 1" />
    <limit
      lower="0"
      upper="0"
      effort="0"
      velocity="0" />
  </joint>
  <link
    name="r_arm_claw_link">
    <inertial>
      <origin
        xyz="-0.017709 0.00074094 -0.047831"
        rpy="0 0 0" />
      <mass
        value="0.13307" />
      <inertia
        ixx="0.00016088"
        ixy="1.0932E-06"
        ixz="-1.102E-05"
        iyy="0.00011679"
        iyz="1.135E-05"
        izz="7.2165E-05" />
    </inertial>
    <visual>
      <origin
        xyz="0 0 0"
        rpy="0 0 0" />
      <geometry>
        <mesh
          filename="r_arm_claw_link.STL" />
      </geometry>
      <material
        name="">
        <color
          rgba="1 1 1 1" />
      </material>
    </visual>
    <collision>
      <origin
        xyz="0 0 0"
        rpy="0 0 0" />
      <geometry>
        <mesh
          filename="r_arm_claw_link.STL" />
      </geometry>
    </collision>
  </link>
  <joint
    name="r_arm_claw_joint"
    type="fixed">
    <origin
      xyz="0.0026637 3.2137E-05 -0.045636"
      rpy="0 0 0" />
    <parent
      link="r_arm_wrist_yaw2_Link" />
    <child
      link="r_arm_claw_link" />
    <axis
      xyz="0 1 0" />
    <limit
      lower="1"
      upper="1"
      effort="1"
      velocity="1" />
  </joint>



  <link
    name="l_leg_hip_roll_Link">
    <inertial>
      <origin
        xyz="0.073997 -2.6118E-05 -0.00038831"
        rpy="0 0 0" />
      <mass
        value="1.2237" />
      <inertia
        ixx="0.0010875"
        ixy="2.5346E-06"
        ixz="4.9227E-06"
        iyy="0.0012014"
        iyz="-2.996E-07"
        izz="0.0021103" />
    </inertial>
    <visual>
      <origin
        xyz="0 0 0"
        rpy="0 0 0" />
      <geometry>
        <mesh
          filename="l_leg_hip_roll_Link.STL" />
      </geometry>
      <material
        name="">
        <color
          rgba="0.64706 0.61961 0.58824 1" />
      </material>
    </visual>
    <!-- <collision>
      <origin
        xyz="0 0 0"
        rpy="0 0 0" />
      <geometry>
        <mesh
          filename="l_leg_hip_roll_Link.STL" />
      </geometry>
    </collision> -->
  </link>
  <joint
    name="l_leg_hip_roll_joint"
    type="revolute">
    <origin
      xyz="-0.0792 0.09002 -0.085"
      rpy="0 0 0" />
    <parent
      link="base_link" />
    <child
      link="l_leg_hip_roll_Link" />
    <axis
      xyz="1 0 0" />
    <limit
      lower="-0.3"
      upper="1"
      effort="90"
      velocity="12" />
  </joint>
  <link
    name="l_leg_hip_yaw_Link">
    <inertial>
      <origin
        xyz="0.00018298 -0.018275 -0.069994"
        rpy="0 0 0" />
      <mass
        value="1.5439" />
      <inertia
        ixx="0.0016181"
        ixy="1.229E-06"
        ixz="-2.3738E-06"
        iyy="0.0028764"
        iyz="2.6967E-06"
        izz="0.0014519" />
    </inertial>
    <visual>
      <origin
        xyz="0 0 0"
        rpy="0 0 0" />
      <geometry>
        <mesh
          filename="l_leg_hip_yaw_Link.STL" />
      </geometry>
      <material
        name="">
        <color
          rgba="0.89804 0.91765 0.92941 1" />
      </material>
    </visual>
    <collision>
      <origin
        xyz="0 0 0"
        rpy="0 0 0" />
      <geometry>
        <mesh
          filename="l_leg_hip_yaw_Link.STL" />
      </geometry>
    </collision>
  </link>
  <joint
    name="l_leg_hip_yaw_joint"
    type="revolute">
    <origin
      xyz="0.0815 0 -0.0375"
      rpy="0 0 0" />
    <parent
      link="l_leg_hip_roll_Link" />
    <child
      link="l_leg_hip_yaw_Link" />
    <axis
      xyz="0 0 1" />
    <limit
      lower="-0.75"
      upper="1.05"
      effort="90"
      velocity="12" />
  </joint>
  <link
    name="l_leg_hip_pitch_Link">
    <inertial>
      <origin
        xyz="0.00263050346808996 0.0505924691116392 -0.0509281264870309"
        rpy="0 0 0" />
      <mass
        value="2.63780166885626" />
      <inertia
        ixx="0.0128050639410327"
        ixy="-7.30670824907572E-06"
        ixz="0.00012322434413997"
        iyy="0.0146659167630542"
        iyz="0.000182392843008207"
        izz="0.00218142025359868" />
    </inertial>
    <visual>
      <origin
        xyz="0 0 0"
        rpy="0 0 0" />
      <geometry>
        <mesh
          filename="l_leg_hip_pitch_Link.STL" />
      </geometry>
      <material
        name="">
        <color
          rgba="1 1 1 1" />
      </material>
    </visual>
    <collision>
      <origin
        xyz="0 0 0"
        rpy="0 0 0" />
      <geometry>
        <mesh
          filename="l_leg_hip_pitch_Link.STL" />
      </geometry>
    </collision>
  </link>
  <joint
    name="l_leg_hip_pitch_joint"
    type="revolute">
    <origin
      xyz="0 0 -0.076"
      rpy="0 -0.2 0" />
    <parent
      link="l_leg_hip_yaw_Link" />
    <child
      link="l_leg_hip_pitch_Link" />
    <axis
      xyz="0 1 0" />
    <limit
      lower="-1.12"
      upper="0.88"
      effort="150"
      velocity="12" />
  </joint>
  <link
    name="l_leg_knee_Link">
    <inertial>
      <origin
        xyz="0.0026677 0.0022197 -0.12804"
        rpy="0 0 0" />
      <mass
        value="1.3457" />
      <inertia
        ixx="0.0022506"
        ixy="-2.3667E-06"
        ixz="-2.2148E-05"
        iyy="0.0022436"
        iyz="-4.5481E-05"
        izz="0.00046377" />
    </inertial>
    <visual>
      <origin
        xyz="0 0 0"
        rpy="0 0 0" />
      <geometry>
        <mesh
          filename="l_leg_knee_Link.STL" />
      </geometry>
      <material
        name="">
        <color
          rgba="1 1 1 1" />
      </material>
    </visual>
    <collision>
      <origin
        xyz="0 0 0"
        rpy="0 0 0" />
      <geometry>
        <mesh
          filename="l_leg_knee_Link.STL" />
      </geometry>
    </collision>
  </link>
  <joint
    name="l_leg_knee_joint"
    type="revolute">
    <origin
      xyz="0 0.032659 -0.27"
      rpy="0 0.4 0" />
    <parent
      link="l_leg_hip_pitch_Link" />
    <child
      link="l_leg_knee_Link" />
    <axis
      xyz="0 1 0" />
    <limit
      lower="-0.28"
      upper="1.6"
      effort="150"
      velocity="12" />
  </joint>
  <link
    name="l_leg_ankle_pitch_Link">
    <inertial>
      <origin
        xyz="0.0010416 3.8669E-09 -9.735E-10"
        rpy="0 0 0" />
      <mass
        value="0.089954" />
      <inertia
        ixx="1.1624E-05"
        ixy="6.8819E-12"
        ixz="-6.205E-13"
        iyy="1.4297E-05"
        iyz="7.1496E-13"
        izz="2.1929E-05" />
    </inertial>
    <visual>
      <origin
        xyz="0 0 0"
        rpy="0 0 0" />
      <geometry>
        <mesh
          filename="l_leg_ankle_pitch_Link.STL" />
      </geometry>
      <material
        name="">
        <color
          rgba="1 1 1 1" />
      </material>
    </visual>
    <!-- <collision>
      <origin
        xyz="0 0 0"
        rpy="0 0 0" />
      <geometry>
        <mesh
          filename="l_leg_ankle_pitch_Link.STL" />
      </geometry>
    </collision> -->
  </link>
  <joint
    name="l_leg_ankle_pitch_joint"
    type="revolute">
    <origin
      xyz="0 0 -0.28"
      rpy="0 -0.2 0" />
    <parent
      link="l_leg_knee_Link" />
    <child
      link="l_leg_ankle_pitch_Link" />
    <axis
      xyz="0 1 0" />
    <limit
      lower="-0.68"
      upper="0.88"
      effort="27"
      velocity="12" />
  </joint>
  <link
    name="l_leg_ankle_roll_Link">
    <inertial>
      <origin
        xyz="0.0095635 2.5209E-05 -0.027782"
        rpy="0 0 0" />
      <mass
        value="0.44211" />
      <inertia
        ixx="0.00017944"
        ixy="-9.8037E-08"
        ixz="2.0143E-05"
        iyy="0.00072413"
        iyz="4.7705E-08"
        izz="0.00087034" />
    </inertial>
    <visual>
      <origin
        xyz="0 0 0"
        rpy="0 0 0" />
      <geometry>
        <mesh
          filename="l_leg_ankle_roll_Link.STL" />
      </geometry>
      <material
        name="">
        <color
          rgba="1 1 1 1" />
      </material>
    </visual>
    <collision>
      <origin
        xyz="0 0 0"
        rpy="0 0 0" />
      <geometry>
        <mesh
          filename="l_leg_ankle_roll_Link.STL" />
      </geometry>
    </collision>
  </link>
  <joint
    name="l_leg_ankle_roll_joint"
    type="revolute">
    <origin
      xyz="0 0 0"
      rpy="0 0 0" />
    <parent
      link="l_leg_ankle_pitch_Link" />
    <child
      link="l_leg_ankle_roll_Link" />
    <axis
      xyz="1 0 0" />
    <limit
      lower="-0.5"
      upper="0.5"
      effort="36"
      velocity="12" />
  </joint>
  <link
    name="r_leg_hip_roll_Link">
    <inertial>
      <origin
        xyz="0.073997 -2.6118E-05 -0.00038831"
        rpy="0 0 0" />
      <mass
        value="1.2237" />
      <inertia
        ixx="0.0010875"
        ixy="2.5346E-06"
        ixz="4.9227E-06"
        iyy="0.0012014"
        iyz="-2.996E-07"
        izz="0.0021103" />
    </inertial>
    <visual>
      <origin
        xyz="0 0 0"
        rpy="0 0 0" />
      <geometry>
        <mesh
          filename="r_leg_hip_roll_Link.STL" />
      </geometry>
      <material
        name="">
        <color
          rgba="0.49804 0.49804 0.49804 1" />
      </material>
    </visual>
    <!-- <collision>
      <origin
        xyz="0 0 0"
        rpy="0 0 0" />
      <geometry>
        <mesh
          filename="r_leg_hip_roll_Link.STL" />
      </geometry>
    </collision> -->
  </link>
  <joint
    name="r_leg_hip_roll_joint"
    type="revolute">
    <origin
      xyz="-0.0792 -0.09002 -0.085"
      rpy="0 0 0" />
    <parent
      link="base_link" />
    <child
      link="r_leg_hip_roll_Link" />
    <axis
      xyz="1 0 0" />
    <limit
      lower="-1"
      upper="0.3"
      effort="90"
      velocity="12" />
  </joint>
  <link
    name="r_leg_hip_yaw_Link">
    <inertial>
      <origin
        xyz="0.00018298 0.018275 -0.069994"
        rpy="0 0 0" />
      <mass
        value="1.5439" />
      <inertia
        ixx="0.0016181"
        ixy="1.229E-06"
        ixz="-2.3738E-06"
        iyy="0.0028764"
        iyz="-2.6967E-06"
        izz="0.0014519" />
    </inertial>
    <visual>
      <origin
        xyz="0 0 0"
        rpy="0 0 0" />
      <geometry>
        <mesh
          filename="r_leg_hip_yaw_Link.STL" />
      </geometry>
      <material
        name="">
        <color
          rgba="0.89804 0.91765 0.92941 1" />
      </material>
    </visual>
    <collision>
      <origin
        xyz="0 0 0"
        rpy="0 0 0" />
      <geometry>
        <mesh
          filename="r_leg_hip_yaw_Link.STL" />
      </geometry>
    </collision>
  </link>
  <joint
    name="r_leg_hip_yaw_joint"
    type="revolute">
    <origin
      xyz="0.0815 0 -0.0375"
      rpy="0 0 0" />
    <parent
      link="r_leg_hip_roll_Link" />
    <child
      link="r_leg_hip_yaw_Link" />
    <axis
      xyz="0 0 1" />
    <limit
      lower="-1.05"
      upper="0.75"
      effort="90"
      velocity="12" />
  </joint>
  <link
    name="r_leg_hip_pitch_Link">
    <inertial>
      <origin
        xyz="0.00263050346808996 -0.0505924691116392 -0.0509281264870309"
        rpy="0 0 0" />
      <mass
        value="2.63780166885626" />
      <inertia
        ixx="0.0128050639410327"
        ixy="-7.30670824907572E-06"
        ixz="0.00012322434413997"
        iyy="0.0146659167630542"
        iyz="0.000182392843008207"
        izz="0.00218142025359868" />
    </inertial>
    <visual>
      <origin
        xyz="0 0 0"
        rpy="0 0 0" />
      <geometry>
        <mesh
          filename="r_leg_hip_pitch_Link.STL" />
      </geometry>
      <material
        name="">
        <color
          rgba="0.89804 0.91765 0.92941 1" />
      </material>
    </visual>
    <collision>
      <origin
        xyz="0 0 0"
        rpy="0 0 0" />
      <geometry>
        <mesh
          filename="r_leg_hip_pitch_Link.STL" />
      </geometry>
    </collision>
  </link>
  <joint
    name="r_leg_hip_pitch_joint"
    type="revolute">
    <origin
      xyz="0 0 -0.076"
      rpy="0 -0.2 0" />
    <parent
      link="r_leg_hip_yaw_Link" />
    <child
      link="r_leg_hip_pitch_Link" />
    <axis
      xyz="0 1 0" />
    <limit
      lower="-1.12"
      upper="0.88"
      effort="150"
      velocity="12" />
  </joint>
  <link
    name="r_leg_knee_Link">
    <inertial>
      <origin
        xyz="0.0026677 -0.0022197 -0.12804"
        rpy="0 0 0" />
      <mass
        value="1.3457" />
      <inertia
        ixx="0.0022506"
        ixy="2.3667E-06"
        ixz="-2.2148E-05"
        iyy="0.0022436"
        iyz="4.5481E-05"
        izz="0.00046377" />
    </inertial>
    <visual>
      <origin
        xyz="0 0 0"
        rpy="0 0 0" />
      <geometry>
        <mesh
          filename="r_leg_knee_Link.STL" />
      </geometry>
      <material
        name="">
        <color
          rgba="0.89804 0.91765 0.92941 1" />
      </material>
    </visual>
    <collision>
      <origin
        xyz="0 0 0"
        rpy="0 0 0" />
      <geometry>
        <mesh
          filename="r_leg_knee_Link.STL" />
      </geometry>
    </collision>
  </link>
  <joint
    name="r_leg_knee_joint"
    type="revolute">
    <origin
      xyz="0 -0.032659 -0.27"
      rpy="0 0.4 0" />
    <parent
      link="r_leg_hip_pitch_Link" />
    <child
      link="r_leg_knee_Link" />
    <axis
      xyz="0 1 0" />
    <limit
      lower="-0.28"
      upper="1.6"
      effort="150"
      velocity="12" />
  </joint>
  <link
    name="r_leg_ankle_pitch_Link">
    <inertial>
      <origin
        xyz="0.0010416 -3.8669E-09 -9.735E-10"
        rpy="0 0 0" />
      <mass
        value="0.089954" />
      <inertia
        ixx="1.1624E-05"
        ixy="-6.8819E-12"
        ixz="-6.205E-13"
        iyy="1.4297E-05"
        iyz="-7.1496E-13"
        izz="2.1929E-05" />
    </inertial>
    <visual>
      <origin
        xyz="0 0 0"
        rpy="0 0 0" />
      <geometry>
        <mesh
          filename="r_leg_ankle_pitch_Link.STL" />
      </geometry>
      <material
        name="">
        <color
          rgba="0.64706 0.61961 0.58824 1" />
      </material>
    </visual>
    <!-- <collision>
      <origin
        xyz="0 0 0"
        rpy="0 0 0" />
      <geometry>
        <mesh
          filename="r_leg_ankle_pitch_Link.STL" />
      </geometry>
    </collision> -->
  </link>
  <joint
    name="r_leg_ankle_pitch_joint"
    type="revolute">
    <origin
      xyz="0 0 -0.28"
      rpy="0 -0.2 0" />
    <parent
      link="r_leg_knee_Link" />
    <child
      link="r_leg_ankle_pitch_Link" />
    <axis
      xyz="0 1 0" />
    <limit
      lower="-0.48"
      upper="0.88"
      effort="36"
      velocity="12" />
  </joint>
  <link
    name="r_leg_ankle_roll_Link">
    <inertial>
      <origin
        xyz="0.0095635 -2.5209E-05 -0.027782"
        rpy="0 0 0" />
      <mass
        value="0.44211" />
      <inertia
        ixx="0.00017944"
        ixy="9.8037E-08"
        ixz="2.0143E-05"
        iyy="0.00072413"
        iyz="-4.7705E-08"
        izz="0.00087034" />
    </inertial>
    <visual>
      <origin
        xyz="0 0 0"
        rpy="0 0 0" />
      <geometry>
        <mesh
          filename="r_leg_ankle_roll_Link.STL" />
      </geometry>
      <material
        name="">
        <color
          rgba="0.89804 0.91765 0.92941 1" />
      </material>
    </visual>
    <collision>
      <origin
        xyz="0 0 0"
        rpy="0 0 0" />
      <geometry>
        <mesh
          filename="r_leg_ankle_roll_Link.STL" />
      </geometry>
    </collision>
  </link>
  <joint
    name="r_leg_ankle_roll_joint"
    type="revolute">
    <origin
      xyz="0 0 0"
      rpy="0 0 0" />
    <parent
      link="r_leg_ankle_pitch_Link" />
    <child
      link="r_leg_ankle_roll_Link" />
    <axis
      xyz="1 0 0" />
    <limit
      lower="-0.5"
      upper="0.5"
      effort="36"
      velocity="12" />
  </joint>
</robot>
